Workbook
Name PhysicalCaseIDs: 'Test Cases'!$A$6:$A$25

Sheet Start Here
A1: OfflineChat Mesh v2 — test workbook
A2: Physical-device acceptance, developer checks, device configurations and delivery timing. All unexecuted cases start Not Run. Expected results describe the target behavior; they are not a claim that the APK passed these device tests.
A5: 1 Prepare the test phones
A6: Use three Android 10+ phones: A sender, B relay, C receiver. A fourth phone is needed for the three-peer concurrency case.
A7: Install the same Mesh 2.0.0 release APK. Turn Wi-Fi/mobile data/hotspot/tethering off; turn Bluetooth on.
A8: A and C exchange signed QR identities, compare the full fingerprints and explicitly verify each other. B needs no A/C contact to relay.
A9: Start mesh using the visible control. Keep relaying enabled. Android 10/11 need the applicable location permission/services; Android 12+ uses Nearby devices.
A10: Record actual phone/OEM/Android/battery settings in Device Register. Keep clocks close. Use unique test messages and preserve bounded diagnostics.
A11: Defaults: 8 hops, 24-hour / 1440-minute TTL, 1024 UTF-8 plaintext bytes, 25 MiB queue plus a 4096-envelope count limit.
A13: 2 Execute and record evidence
A14: P0 = core acceptance/security; P1 = extended recovery/platform checks. Complete P0 first. Mark Passed, Failed, Blocked or Not Applicable only after recording actual observations/evidence. Leave unexecuted cases Not Run.
A15: Existing authenticated connections and new encounters while already locked are different screen-off tests. Test fresh messages after 5, 15, 30 and 60 minutes idle. A notification is not proof of relaying.
... A21: 3 Progress — automatic counts
A22: Suite | B22: Total | C22: Not Run | D22: Passed | E22: Failed | F22: Blocked | G22: Not Applicable | H22: Pass %
A23: Test Cases | B23: 20 | C23: =COUNTIF('Test Cases'!$I$6:$I$25,"Not Run") -> 20 | D23: =COUNTIF('Test Cases'!$I$6:$I$25,"Passed") -> 0 | E23: =COUNTIF('Test Cases'!$I$6:$I$25,"Failed") -> 0 | F23: =COUNTIF('Test Cases'!$I$6:$I$25,"Blocked") -> 0 | G23: =COUNTIF('Test Cases'!$I$6:$I$25,"Not Applicable") -> 0 | H23: =IF(B23-G23=0,"",D23/(B23-G23)) -> 0
A24: Developer Tests | B24: 13 | C24: =COUNTIF('Developer Tests'!$I$6:$I$18,"Not Run") -> 13 | D24: =COUNTIF('Developer Tests'!$I$6:$I$18,"Passed") -> 0 | E24: =COUNTIF('Developer Tests'!$I$6:$I$18,"Failed") -> 0 | F24: =COUNTIF('Developer Tests'!$I$6:$I$18,"Blocked") -> 0 | G24: =COUNTIF('Developer Tests'!$I$6:$I$18,"Not Applicable") -> 0 | H24: =IF(B24-G24=0,"",D24/(B24-G24)) -> 0
A26: Timing record warnings | B26: =COUNTIF('Timing Runs'!$O$6:$O$205,"?*") -> 0
A28: 4 Saved automated baseline and limits
A29: Saved implementation baseline: 50 Flutter tests and 85 native tests passed; analyzer, debug/release builds and APK checks passed. These are not physical BLE or KeyStore device results. Four vault instrumented tests compiled but have not run on a device/emulator.
A32: This is an experimental custom protocol without independent security audit. Physical BLE, screen-off/new-encounter behavior, camera/background/OEM behavior and 2 km routing remain unverified. Windows v0.2 is a separate legacy direct-chat app and cannot join Android Mesh v2.
A35: APK / source baseline | C35: 2.0.0 (code 3); implementation commit 1d527447400e97633cb6a1b0726e3bc576989d4b
A36: Workbook generated | C36: 2026-10-22 15:28 +04 — blank results template
A38: 5 Open a worksheet or reference
A39: Test Cases | D39: Download Android release APK
A40: Developer Tests | D40: Full device test plan on GitHub
A41: Device Register | D41: Executed automated checks
A42: Timing Runs | D42: Limitations and unverified behavior
A43: Timing Summary

Sheet Device Register
A1: Device register
A2: Use arbitrary labels such as A/B/C/D. Record observed configuration; do not enter private keys or personal device identifiers. D is optional unless running the three-peer concurrency test.
A5: Device ID | B5: Planned role | C5: Model / manufacturer | D5: Android version | E5: API level | F5: Security patch | G5: OS / firmware build | H5: Installed app version | I5: BLE advertising | J5: BLE concurrent roles | K5: Bluetooth permission | L5: Location services | M5: Notification permission | N5: Battery / background mode | O5: Battery % / charging | P5: Notes
A6: A | B6: Sender | I6: Unknown | J6: Unknown
A7: B | B7: Relay | I7: Unknown | J7: Unknown
A8: C | B8: Receiver | I8: Unknown | J8: Unknown
A9: D | B9: Additional peer (optional) | I9: Unknown | J9: Unknown

Sheet Test Cases
A1: Mesh v2 — Test Cases
A2: Expected results are acceptance criteria, not evidence of a pass. Yellow cells are for your results. All cases start Not Run. Record separate runs for subcases/device configurations.
A5: Test ID | B5: Priority | C5: Area | D5: Test case | E5: Preconditions | F5: Steps | G5: Expected result | H5: Actual result | I5: Status | J5: Tester | K5: Test date | L5: Device IDs | M5: Run / message IDs | N5: Evidence / diagnostics | O5: Notes / caveats
A6: T01 | B6: P0 | C6: Identity | D6: Identity survives reopen and reboot | E6: Fresh test installation; record the initial fingerprint. | F6: 1. Create identity A and record its fingerprint. 2. Close and reopen the app. 3. Restart the phone, unlock it and reopen the app. Start mesh again through the visible control. | G6: The same identity/fingerprint remains. Any pre-existing history/queue remains. No silent replacement identity. | I6: Not Run | O6: Reinstall/clear-data is different from reopen/reboot: it creates a new identity. Do not clear data in this test.
A7: T02 | B7: P0 | C7: Contacts | D7: QR contact verification and invalid import | E7: A and C have distinct identities. Camera is available or use signed QR text. | F7: 1. Import each other's QR on A and C; compare the full fingerprint in person. 2. Try completing import without explicitly confirming verification. 3. Try malformed/altered QR text and the phone's own QR. | G7: Only valid, explicitly verified other-device contacts are saved. Invalid/self/unconfirmed imports are rejected clearly. | I7: Not Run | O7: B does not need A/C as contacts to relay their ciphertext.
A8: T03 | B8: P0 | C8: Direct BLE | D8: Direct messaging with Internet unavailable | E8: A/C verified; B stopped. Wi-Fi, mobile data, hotspot and tethering off; Bluetooth on. | F8: 1. Place A and C nearby and start mesh on both. 2. Confirm a real authenticated peer connection. 3. Send a unique message in each direction and record arrival and receipt times. | G8: Exact text arrives once. Signed receipts return. No Internet path is required. | I8: Not Run | O8: Use the downloaded release APK. A service notification alone is not proof of a working radio link.
A9: T04 | B9: P0 | C9: Multi-hop | D9: A to B to C with no direct A/C path | E9: A/C remain beyond usable direct range; B can communicate with each separately. | F9: 1. With B stopped, test fresh A-to-C messages and inspect peer/diagnostic state. 2. Start B between A and C. Verify authenticated A/B and B/C links, with no A/C link. 3. Send a fresh uniquely numbered message and observe C plus receipt return to A. 4. Stop B and repeat the negative control. Repeat in the reverse direction. | G9: C receives exactly once through B; A receives C's receipt. Fresh messages cannot use the isolated route with B stopped. | I9: Not Run | O9: Two minutes without delivery alone does not prove radio isolation. Use physical separation, repeated controls and diagnostics; discard accidental direct-link runs.
A10: T05 | B10: P0 | C10: Receipts | D10: Relay custody must not mean Delivered | E10: A/B can connect; C is unreachable. B relaying enabled. | F10: 1. Send a fresh A-to-C message. 2. Wait for confirmed custody on B and record queue/diagnostic evidence. 3. Keep C unreachable while inspecting A's status. | G10: A may show Relayed but never Delivered solely from B's custody or fragment ACKs. | I10: Not Run | O10: Fast valid transfers may skip a visibly rendered Pending/Relayed state. The requirement is no false Delivered, not observing every transient UI state.
A11: T06 | B11: P0 | C11: Store-forward | D11: Courier delivery during a later encounter | E11: A/C out of direct range for the entire test; message remains within TTL. | F11: 1. Place A/B together with C absent; send and confirm B's custody. 2. Turn A's Bluetooth off and take B to C. 3. Start/retain B/C mesh and observe the unique message on C. | G11: C receives the queued message once while A is unreachable. B cannot read the message body. | I11: Not Run | O11: The moving relay supplies an encounter path; this does not prove continuous 2 km radio coverage.
A12: T07 | B12: P0 | C12: Receipts | D12: Receipt returns after sender absence | E12: Complete T06. A must still be unreachable when C receives. | F12: 1. Keep A unreachable and confirm it has not yet obtained a delivery receipt. 2. Let B obtain C's signed receipt, then move B away from C. 3. Return B to A; re-enable/start A's mesh and record the Delivered transition. | G12: A becomes Delivered only after C's authenticated receipt reaches A. C still has only one copy. | I12: Not Run | O12: Recipient arrival and sender receipt-confirmed delivery are separate timing events.
A13: T08 | B13: P0 | C13: Persistence | D13: Restart relay after confirmed custody | E13: B has durably accepted a unique A-to-C message; C remains absent. | F13: 1. Record B's identity and nonzero queue after confirmed custody. 2. Stop mesh and restart B's process without clearing app data. 3. Reopen B, start mesh, take it to C and then return it to A for the receipt. | G13: Identity and queued envelope survive. C receives once; the receipt can later return. | I13: Not Run | O13: Repeat process termination separately from graceful stop. Do not claim operation while force-stopped.
A14: T09 | B14: P0 | C14: Screen off | D14: Locked relay with existing connections | E14: Isolated A/C; working authenticated A/B and B/C links. Record default battery settings. | F14: 1. Establish a screen-on baseline, then lock B and leave A/C awake. 2. After 5, 15, 30 and 60 minutes idle, send a fresh uniquely numbered A-to-C message. 3. Keep B locked; record C arrival, A receipt, service state and interruptions. | G14: B forwards and receipts return without unlocking B. Record failures/delays honestly for each interval/device. | I14: Not Run | O14: Run each interval as a separately recorded timing run. A notification alone is not evidence that relaying continued.
A15: T10 | B15: P0 | C15: Screen off | D15: New encounters while relay is already locked | E15: B mesh started with no nearby peers; A/C stay isolated. Record battery settings. | F15: 1. Lock B before A or C is nearby. 2. After 5, 15, 30 and 60 minutes idle, bring A into B's range and send a message for C. 3. Keep B locked; make A unreachable and later bring B/C into range. 4. Observe discovery, message arrival and later receipt return without unlocking B. | G15: New peers can be discovered/authenticated and the message forwarded while B stays locked. | I15: Not Run | O15: This tests background discovery, not merely survival of existing connections. Use separate runs per idle interval.
A16: T11 | B16: P1 | C16: Screen off | D16: Receiver locked during delivery | E16: A/C verified and a known valid route exists. | F16: 1. Lock C, then send a fresh message. 2. Observe generic notification and receipt return where permitted. 3. Unlock C and inspect history; repeat with A locked during receipt return. | G16: C stores the message once and emits its receipt. Notification contains no plaintext. A shows the authenticated result after reopening. | I16: Not Run | O16: Notification denial on Android 13+ is a separate test and must not be mistaken for message loss.
A17: T12 | B17: P0 | C17: Recovery | D17: Bluetooth interruption during transfer | E17: Known route; choose a message near the 1024-byte limit to exercise fragmentation. | F17: 1. Begin a transfer and interrupt B's Bluetooth while it is in progress. 2. Record the failure/pending state; restore Bluetooth and encounter peers again. 3. Repeat and confirm recovery using diagnostics. | G17: No truncated plaintext, false Delivered or duplicated bubble. Durable envelopes reconcile after reconnection. | I17: Not Run | O17: If transfer completed before interruption, that run does not prove interrupted-transfer recovery.
... A25: T20 | B25: P1 | C25: Battery / OS | D25: Battery saver and background restriction matrix | E25: First establish T09/T10 baselines under recorded default battery settings. | F25: 1. Repeat existing-link and new-encounter screen-off tests under battery saver. 2. Repeat with the app background-restricted; optionally compare Unrestricted mode. 3. Record model/OEM, Android build, idle duration, service state, failures and recovery. | G25: Actual behavior is documented for each configuration. Interruptions are recorded, with accurate UI state and retained messages after restarting. | I25: Not Run | O25: There is no blanket promise of continuous background delivery. A notification is not proof of radio activity.

Sheet Developer Tests
A1: Mesh v2 — Developer Tests
A2: Expected results are acceptance criteria, not evidence of a pass. Yellow cells are for your results. All cases start Not Run. Record separate runs for subcases/device configurations.
A5: Test ID | B5: Priority | C5: Area | D5: Test case | E5: Preconditions | F5: Steps | G5: Expected result | H5: Actual result | I5: Status | J5: Tester | K5: Test date | L5: Device IDs | M5: Run / message IDs | N5: Evidence / diagnostics | O5: Notes / caveats
A6: D01 | B6: P0 | C6: AndroidKeyStore | D6: Persisted keys and encrypted history reload | E6: Android device/emulator supporting AndroidKeyStore; isolated test preferences. | F6: 1. Run encryptedKeysPersistAndHistorySurvivesReloadAndRename. | G6: Identity/private signing capability and encrypted history survive reload; renamed identity persists; persisted keysets are encrypted. | I6: Not Run | O6: Part of AndroidIdentityVaultInstrumentedTest. Compilation passed; device execution has not run.
A7: D02 | B7: P0 | C7: AndroidKeyStore | D7: Tampered ciphertext or swapped key purpose | E7: Isolated device-test vault; preserve unrelated application data. | F7: 1. Run changedCiphertextOrSwappedPurposeFailsWithoutCreatingNewIdentity. | G7: Changed ciphertext/purpose swapping is rejected; unaffected slots remain intact; no replacement identity is generated. | I7: Not Run | O7: Do not weaken production key protection to inspect data.
A8: D03 | B8: P0 | C8: AndroidKeyStore | D8: Partial or unsupported vault fails closed | E8: Isolated device-test vault. | F8: 1. Run partialOrUnsupportedVaultFailsClosed. | G8: Missing slots/unsupported vault versions fail closed without repairing the state by creating new private keys. | I8: Not Run
A9: D04 | B9: P0 | C9: AndroidKeyStore | D9: Entire missing vault does not silently regenerate | E9: Isolated device-test preferences; explicit creation is permitted only for onboarding. | F9: 1. Run completelyMissingVaultDoesNotReplaceIdentityOnNormalLoad. | G9: Normal loading of empty/deleted vault fails without writing replacement keys; explicit initial creation remains possible. | I9: Not Run
A10: D05 | B10: P0 | C10: Protocol security | D10: Tampered packet, identity or signed route | E10: Dedicated crafted-packet harness/test build; keep production validation enabled. | F10: 1. Inject changed ciphertext/signature, wrong-recipient data and malformed identities. 2. Try broken/stripped route edges, hop reset, repeated peers and unsupported versions. | G10: Invalid traffic is rejected with bounded work/logging; no readable message, custody success or forged Delivered state. | I10: Not Run | O10: Existing unit coverage is not proof of equivalent behavior through physical GATT.
A11: D06 | B11: P0 | C11: Protocol security | D11: Forged or mismatched delivery receipt | E11: A has an outgoing message for C; B has no C private signing key. | F11: 1. Try a receipt signed by B, a wrong message ID/digest, wrong recipient and an invalid delivery time. | G11: Only a valid receipt authenticated as original recipient C and bound to the original message can mark A Delivered. | I11: Not Run
A12: D07 | B12: P0 | C12: Replay / sessions | D12: Replay and conflicting-ID traffic over BLE | E12: Harness can retain exact signed frames/controls; use fresh authenticated sessions. | F12: 1. Replay a control within its session and into a fresh session. 2. Replay an accepted envelope after reconnect/restart; reuse its ID with different immutable content. | G12: Session replay/reordering and conflicting IDs are rejected. An authentic duplicate creates no second history entry. | I12: Not Run
A13: D08 | B13: P0 | C13: Storage privacy | D13: Inspect local relay/history confidentiality | E13: Dedicated test device/build with authorized inspection access; unique test text. | F13: 1. Inspect B's database/journal and diagnostics after relay custody. 2. Inspect endpoint history/keyset persistence and backup/transfer exclusions. | G13: No message plaintext/private key is persisted in relay data/logs. New history is locally encrypted; private keysets are wrapped, with backup excluded. | I13: Not Run | O13: A missing chat bubble alone is insufficient proof of ciphertext-only storage. Legacy v0.2 data is not automatically encrypted/migrated.
A14: D09 | B14: P0 | C14: Capacity | D14: Byte/count quotas and atomic receipt admission | E14: Controlled load tool; known quota and queue state; avoid filling personal device storage. | F14: 1. Reach the configured byte quota and separately the 4096-envelope count limit. 2. Leave one slot, then test recipient admission that needs both message and receipt. 3. Allow legitimate expiry/cleanup and retry. | G14: Admission never exceeds either bound. Failed admission sends no custody success; message/history/receipt are atomic. Existing accepted data is not silently discarded. | I14: Not Run | O14: Default 25 MiB; settings allow 1–100 MiB. Raising bytes does not raise the 4096-envelope count limit.
A15: D10 | B15: P0 | C15: Framing | D15: Loss/reorder/duplication, MTU and interrupted journals | E15: Controlled BLE fault injection plus durable journal inspection. | F15: 1. Exercise MTU 23 and larger negotiated payloads; lose/reorder/duplicate/corrupt frames and ACKs. 2. Interrupt the process at fragment/ACK boundaries and then reconnect. 3. Check per-peer targeting and full-envelope reconciliation after interruption. | G15: Bounded retry/backoff or visible failure; no mixed/truncated payload, false custody or false Delivered. Valid envelopes recover through durable storage/reconciliation. | I15: Not Run | O15: Distinguish full-envelope retry from fine-grained fragment resumption; record what actually happens.
A16: D11 | B16: P1 | C16: Concurrency | D16: Three simultaneous peers and excess-peer handling | E16: Four physical phones required: B plus three peers. Optional fifth for excess-link attempt. | F16: 1. Connect three peers to B, with traffic in both GATT roles. 2. Observe ordering, subscriptions, address-targeted notifications and reconnect behavior. 3. Attempt an additional peer if equipment is available. | G16: Up to three links behave correctly; additional links are bounded/deferred cleanly. No cross-peer data mixing. | I16: Not Run | O16: Three phones total exercise only two peers on B, not its three-peer capacity.
A17: D12 | B17: P1 | C17: Clock / expiry | D17: Clock skew, TTL validation and replay retention | E17: Controlled clocks/harness; restore normal clocks afterward. | F17: 1. Exercise permitted small skew and future/expired envelopes outside policy. 2. Restart around expiry/cleanup and attempt replay while retained tombstones apply. | G17: Policy-valid traffic works; invalid lifetimes are refused. Cleanup/replay handling remains consistent across restart. | I17: Not Run | O17: The implementation assumes reasonably synchronized offline clocks; there is no network time service.
A18: D13 | B18: P1 | C18: Receipt lifetime | D18: Short recipient default must not expire return receipt early | E18: A original TTL 24 hours; C default TTL 1 minute; A unreachable during recipient delivery. | F18: 1. Deliver A's message to C through B. 2. Wait more than one minute before taking B back to A, while original message remains valid. 3. Observe receipt return and sender status. | G18: The authenticated return receipt still reaches A and marks Delivered within the original permitted lifetime. | I18: Not Run

Sheet Timing Runs
A1: Delivery timing — observed runs
A2: 200 blank run templates. Enter full date + time, using synchronized clocks. Record actual arrival on C separately from Delivered on A; chat bubble timestamps are creation times. Blue cells calculate minutes. Failed/expired runs must remain in the log.
A5: Run ID | B5: Test Case ID | C5: Route / scenario | D5: Distance km | E5: Actual hop count | F5: Sender device | G5: Relay devices | H5: Receiver device | I5: Send time | J5: Receiver arrival time | K5: Sender Delivered time | L5: Arrival delay min | M5: Receipt delay min | N5: Outcome | O5: Record check | P5: Idle before send min | Q5: Screen state | R5: Battery mode | S5: Message TTL min | T5: Configured hop limit | U5: Message ID / test text | V5: Notes / evidence
A6: RUN-001 | L6: =IF(AND(ISNUMBER(I6),ISNUMBER(J6),J6>=I6),(J6-I6)*1440,"") | M6: =IF(AND(ISNUMBER(I6),ISNUMBER(K6),K6>=I6),(K6-I6)*1440,"") | N6: Not Run | O6: =IF(N6="Not Run","",IF(AND(OR(N6="Delivered",N6="Received; receipt pending"),NOT(ISNUMBER(L6))),"Enter valid send and arrival timestamps",IF(AND(N6="Delivered",NOT(ISNUMBER(M6))),"Enter valid sender Delivered timestamp",IF(AND(ISNUMBER(J6),ISNUMBER(K6),K6<J6),"Check clock order: receipt precedes arrival",""))))
A7: RUN-002 | L7: =IF(AND(ISNUMBER(I7),ISNUMBER(J7),J7>=I7),(J7-I7)*1440,"") | M7: =IF(AND(ISNUMBER(I7),ISNUMBER(K7),K7>=I7),(K7-I7)*1440,"") | N7: Not Run | O7: =IF(N7="Not Run","",IF(AND(OR(N7="Delivered",N7="Received; receipt pending"),NOT(ISNUMBER(L7))),"Enter valid send and arrival timestamps",IF(AND(N7="Delivered",NOT(ISNUMBER(M7))),"Enter valid sender Delivered timestamp",IF(AND(ISNUMBER(J7),ISNUMBER(K7),K7<J7),"Check clock order: receipt precedes arrival",""))))
A8: RUN-003 | L8: =IF(AND(ISNUMBER(I8),ISNUMBER(J8),J8>=I8),(J8-I8)*1440,"") | M8: =IF(AND(ISNUMBER(I8),ISNUMBER(K8),K8>=I8),(K8-I8)*1440,"") | N8: Not Run | O8: =IF(N8="Not Run","",IF(AND(OR(N8="Delivered",N8="Received; receipt pending"),NOT(ISNUMBER(L8))),"Enter valid send and arrival timestamps",IF(AND(N8="Delivered",NOT(ISNUMBER(M8))),"Enter valid sender Delivered timestamp",IF(AND(ISNUMBER(J8),ISNUMBER(K8),K8<J8),"Check clock order: receipt precedes arrival",""))))
A9: RUN-004 | L9: =IF(AND(ISNUMBER(I9),ISNUMBER(J9),J9>=I9),(J9-I9)*1440,"") | M9: =IF(AND(ISNUMBER(I9),ISNUMBER(K9),K9>=I9),(K9-I9)*1440,"") | N9: Not Run | O9: =IF(N9="Not Run","",IF(AND(OR(N9="Delivered",N9="Received; receipt pending"),NOT(ISNUMBER(L9))),"Enter valid send and arrival timestamps",IF(AND(N9="Delivered",NOT(ISNUMBER(M9))),"Enter valid sender Delivered timestamp",IF(AND(ISNUMBER(J9),ISNUMBER(K9),K9<J9),"Check clock order: receipt precedes arrival",""))))
A10: RUN-005 | L10: =IF(AND(ISNUMBER(I10),ISNUMBER(J10),J10>=I10),(J10-I10)*1440,"") | M10: =IF(AND(ISNUMBER(I10),ISNUMBER(K10),K10>=I10),(K10-I10)*1440,"") | N10: Not Run | O10: =IF(N10="Not Run","",IF(AND(OR(N10="Delivered",N10="Received; receipt pending"),NOT(ISNUMBER(L10))),"Enter valid send and arrival timestamps",IF(AND(N10="Delivered",NOT(ISNUMBER(M10))),"Enter valid sender Delivered timestamp",IF(AND(ISNUMBER(J10),ISNUMBER(K10),K10<J10),"Check clock order: receipt precedes arrival",""))))
A11: RUN-006 | L11: =IF(AND(ISNUMBER(I11),ISNUMBER(J11),J11>=I11),(J11-I11)*1440,"") | M11: =IF(AND(ISNUMBER(I11),ISNUMBER(K11),K11>=I11),(K11-I11)*1440,"") | N11: Not Run | O11: =IF(N11="Not Run","",IF(AND(OR(N11="Delivered",N11="Received; receipt pending"),NOT(ISNUMBER(L11))),"Enter valid send and arrival timestamps",IF(AND(N11="Delivered",NOT(ISNUMBER(M11))),"Enter valid sender Delivered timestamp",IF(AND(ISNUMBER(J11),ISNUMBER(K11),K11<J11),"Check clock order: receipt precedes arrival",""))))
A12: RUN-007 | L12: =IF(AND(ISNUMBER(I12),ISNUMBER(J12),J12>=I12),(J12-I12)*1440,"") | M12: =IF(AND(ISNUMBER(I12),ISNUMBER(K12),K12>=I12),(K12-I12)*1440,"") | N12: Not Run | O12: =IF(N12="Not Run","",IF(AND(OR(N12="Delivered",N12="Received; receipt pending"),NOT(ISNUMBER(L12))),"Enter valid send and arrival timestamps",IF(AND(N12="Delivered",NOT(ISNUMBER(M12))),"Enter valid sender Delivered timestamp",IF(AND(ISNUMBER(J12),ISNUMBER(K12),K12<J12),"Check clock order: receipt precedes arrival",""))))
A13: RUN-008 | L13: =IF(AND(ISNUMBER(I13),ISNUMBER(J13),J13>=I13),(J13-I13)*1440,"") | M13: =IF(AND(ISNUMBER(I13),ISNUMBER(K13),K13>=I13),(K13-I13)*1440,"") | N13: Not Run | O13: =IF(N13="Not Run","",IF(AND(OR(N13="Delivered",N13="Received; receipt pending"),NOT(ISNUMBER(L13))),"Enter valid send and arrival timestamps",IF(AND(N13="Delivered",NOT(ISNUMBER(M13))),"Enter valid sender Delivered timestamp",IF(AND(ISNUMBER(J13),ISNUMBER(K13),K13<J13),"Check clock order: receipt precedes arrival",""))))
A14: RUN-009 | L14: =IF(AND(ISNUMBER(I14),ISNUMBER(J14),J14>=I14),(J14-I14)*1440,"") | M14: =IF(AND(ISNUMBER(I14),ISNUMBER(K14),K14>=I14),(K14-I14)*1440,"") | N14: Not Run | O14: =IF(N14="Not Run","",IF(AND(OR(N14="Delivered",N14="Received; receipt pending"),NOT(ISNUMBER(L14))),"Enter valid send and arrival timestamps",IF(AND(N14="Delivered",NOT(ISNUMBER(M14))),"Enter valid sender Delivered timestamp",IF(AND(ISNUMBER(J14),ISNUMBER(K14),K14<J14),"Check clock order: receipt precedes arrival",""))))
A15: RUN-010 | L15: =IF(AND(ISNUMBER(I15),ISNUMBER(J15),J15>=I15),(J15-I15)*1440,"") | M15: =IF(AND(ISNUMBER(I15),ISNUMBER(K15),K15>=I15),(K15-I15)*1440,"") | N15: Not Run | O15: =IF(N15="Not Run","",IF(AND(OR(N15="Delivered",N15="Received; receipt pending"),NOT(ISNUMBER(L15))),"Enter valid send and arrival timestamps",IF(AND(N15="Delivered",NOT(ISNUMBER(M15))),"Enter valid sender Delivered timestamp",IF(AND(ISNUMBER(J15),ISNUMBER(K15),K15<J15),"Check clock order: receipt precedes arrival",""))))
A16: RUN-011 | L16: =IF(AND(ISNUMBER(I16),ISNUMBER(J16),J16>=I16),(J16-I16)*1440,"") | M16: =IF(AND(ISNUMBER(I16),ISNUMBER(K16),K16>=I16),(K16-I16)*1440,"") | N16: Not Run | O16: =IF(N16="Not Run","",IF(AND(OR(N16="Delivered",N16="Received; receipt pending"),NOT(ISNUMBER(L16))),"Enter valid send and arrival timestamps",IF(AND(N16="Delivered",NOT(ISNUMBER(M16))),"Enter valid sender Delivered timestamp",IF(AND(ISNUMBER(J16),ISNUMBER(K16),K16<J16),"Check clock order: receipt precedes arrival",""))))
A17: RUN-012 | L17: =IF(AND(ISNUMBER(I17),ISNUMBER(J17),J17>=I17),(J17-I17)*1440,"") | M17: =IF(AND(ISNUMBER(I17),ISNUMBER(K17),K17>=I17),(K17-I17)*1440,"") | N17: Not Run | O17: =IF(N17="Not Run","",IF(AND(OR(N17="Delivered",N17="Received; receipt pending"),NOT(ISNUMBER(L17))),"Enter valid send and arrival timestamps",IF(AND(N17="Delivered",NOT(ISNUMBER(M17))),"Enter valid sender Delivered timestamp",IF(AND(ISNUMBER(J17),ISNUMBER(K17),K17<J17),"Check clock order: receipt precedes arrival",""))))
... A205: RUN-200 | L205: =IF(AND(ISNUMBER(I205),ISNUMBER(J205),J205>=I205),(J205-I205)*1440,"") | M205: =IF(AND(ISNUMBER(I205),ISNUMBER(K205),K205>=I205),(K205-I205)*1440,"") | N205: Not Run | O205: =IF(N205="Not Run","",IF(AND(OR(N205="Delivered",N205="Received; receipt pending"),NOT(ISNUMBER(L205))),"Enter valid send and arrival timestamps",IF(AND(N205="Delivered",NOT(ISNUMBER(M205))),"Enter valid sender Delivered timestamp",IF(AND(ISNUMBER(J205),ISNUMBER(K205),K205<J205),"Check clock order: receipt precedes arrival",""))))

Sheet Timing Summary
A1: Timing summary — successful observed runs
A2: Counts and min/median/max update from Timing Runs. Failed/expired attempts stay in the arrival ratio; this is not the acceptance-test pass rate. Negative tests intentionally may not deliver. Blank metrics mean no valid observations. Fix Record check warnings. Times are minutes, without a guaranteed maximum.
A5: Test Case ID | B5: Case | C5: Completed attempts | D5: Arrived at receiver | E5: Failed | F5: Expired | G5: Blocked | H5: Arrival success % | I5: Min arrival min | J5: Median arrival min | K5: Max arrival min | L5: Min receipt min | M5: Median receipt min | N5: Max receipt min
A6: T01 | B6: Identity survives reopen and reboot | C6: =COUNTIFS('Timing Runs'!$B$6:$B$205,$A6,'Timing Runs'!$N$6:$N$205,"Delivered")+COUNTIFS('Timing Runs'!$B$6:$B$205,$A6,'Timing Runs'!$N$6:$N$205,"Received; receipt pending")+COUNTIFS('Timing Runs'!$B$6:$B$205,$A6,'Timing Runs'!$N$6:$N$205,"Failed")+COUNTIFS('Timing Runs'!$B$6:$B$205,$A6,'Timing Runs'!$N$6:$N$205,"Expired") -> 0 | D6: =COUNTIFS('Timing Runs'!$B$6:$B$205,$A6,'Timing Runs'!$N$6:$N$205,"Delivered")+COUNTIFS('Timing Runs'!$B$6:$B$205,$A6,'Timing Runs'!$N$6:$N$205,"Received; receipt pending") -> 0 | E6: =COUNTIFS('Timing Runs'!$B$6:$B$205,$A6,'Timing Runs'!$N$6:$N$205,"Failed") -> 0 | F6: =COUNTIFS('Timing Runs'!$B$6:$B$205,$A6,'Timing Runs'!$N$6:$N$205,"Expired") -> 0 | G6: =COUNTIFS('Timing Runs'!$B$6:$B$205,$A6,'Timing Runs'!$N$6:$N$205,"Blocked") -> 0 | H6: =IF(C6=0,"",D6/C6) | I6: {=IF(SUMPRODUCT(('Timing Runs'!$B$6:$B$205=$A6)*ISNUMBER('Timing Runs'!$L$6:$L$205)*(('Timing Runs'!$N$6:$N$205="Delivered")+('Timing Runs'!$N$6:$N$205="Received; receipt pending"))*('Timing Runs'!$O$6:$O$205=""))=0,"",MIN(IF(('Timing Runs'!$B$6:$B$205=$A6)*ISNUMBER('Timing Runs'!$L$6:$L$205)*(('Timing Runs'!$N$6:$N$205="Delivered")+('Timing Runs'!$N$6:$N$205="Received; receipt pending"))*('Timing Runs'!$O$6:$O$205=""),'Timing Runs'!$L$6:$L$205)))} | J6: {=IF(SUMPRODUCT(('Timing Runs'!$B$6:$B$205=$A6)*ISNUMBER('Timing Runs'!$L$6:$L$205)*(('Timing Runs'!$N$6:$N$205="Delivered")+('Timing Runs'!$N$6:$N$205="Received; receipt pending"))*('Timing Runs'!$O$6:$O$205=""))=0,"",MEDIAN(IF(('Timing Runs'!$B$6:$B$205=$A6)*ISNUMBER('Timing Runs'!$L$6:$L$205)*(('Timing Runs'!$N$6:$N$205="Delivered")+('Timing Runs'!$N$6:$N$205="Received; receipt pending"))*('Timing Runs'!$O$6:$O$205=""),'Timing Runs'!$L$6:$L$205)))} | K6: {=IF(SUMPRODUCT(('Timing Runs'!$B$6:$B$205=$A6)*ISNUMBER('Timing Runs'!$L$6:$L$205)*(('Timing Runs'!$N$6:$N$205="Delivered")+('Timing Runs'!$N$6:$N$205="Received; receipt pending"))*('Timing Runs'!$O$6:$O$205=""))=0,"",MAX(IF(('Timing Runs'!$B$6:$B$205=$A6)*ISNUMBER('Timing Runs'!$L$6:$L$205)*(('Timing Runs'!$N$6:$N$205="Delivered")+('Timing Runs'!$N$6:$N$205="Received; receipt pending"))*('Timing Runs'!$O$6:$O$205=""),'Timing Runs'!$L$6:$L$205)))} | L6: {=IF(SUMPRODUCT(('Timing Runs'!$B$6:$B$205=$A6)*ISNUMBER('Timing Runs'!$M$6:$M$205)*('Timing Runs'!$N$6:$N$205="Delivered")*('Timing Runs'!$O$6:$O$205=""))=0,"",MIN(IF(('Timing Runs'!$B$6:$B$205=$A6)*ISNUMBER('Timing Runs'!$M$6:$M$205)*('Timing Runs'!$N$6:$N$205="Delivered")*('Timing Runs'!$O$6:$O$205=""),'Timing Runs'!$M$6:$M$205)))} | M6: {=IF(SUMPRODUCT(('Timing Runs'!$B$6:$B$205=$A6)*ISNUMBER('Timing Runs'!$M$6:$M$205)*('Timing Runs'!$N$6:$N$205="Delivered")*('Timing Runs'!$O$6:$O$205=""))=0,"",MEDIAN(IF(('Timing Runs'!$B$6:$B$205=$A6)*ISNUMBER('Timing Runs'!$M$6:$M$205)*('Timing Runs'!$N$6:$N$205="Delivered")*('Timing Runs'!$O$6:$O$205=""),'Timing Runs'!$M$6:$M$205)))} | N6: {=IF(SUMPRODUCT(('Timing Runs'!$B$6:$B$205=$A6)*ISNUMBER('Timing Runs'!$M$6:$M$205)*('Timing Runs'!$N$6:$N$205="Delivered")*('Timing Runs'!$O$6:$O$205=""))=0,"",MAX(IF(('Timing Runs'!$B$6:$B$205=$A6)*ISNUMBER('Timing Runs'!$M$6:$M$205)*('Timing Runs'!$N$6:$N$205="Delivered")*('Timing Runs'!$O$6:$O$205=""),'Timing Runs'!$M$6:$M$205)))}
A7: T02 | B7: QR contact verification and invalid import | C7: =COUNTIFS('Timing Runs'!$B$6:$B$205,$A7,'Timing Runs'!$N$6:$N$205,"Delivered")+COUNTIFS('Timing Runs'!$B$6:$B$205,$A7,'Timing Runs'!$N$6:$N$205,"Received; receipt pending")+COUNTIFS('Timing Runs'!$B$6:$B$205,$A7,'Timing Runs'!$N$6:$N$205,"Failed")+COUNTIFS('Timing Runs'!$B$6:$B$205,$A7,'Timing Runs'!$N$6:$N$205,"Expired") -> 0 | D7: =COUNTIFS('Timing Runs'!$B$6:$B$205,$A7,'Timing Runs'!$N$6:$N$205,"Delivered")+COUNTIFS('Timing Runs'!$B$6:$B$205,$A7,'Timing Runs'!$N$6:$N$205,"Received; receipt pending") -> 0 | E7: =COUNTIFS('Timing Runs'!$B$6:$B$205,$A7,'Timing Runs'!$N$6:$N$205,"Failed") -> 0 | F7: =COUNTIFS('Timing Runs'!$B$6:$B$205,$A7,'Timing Runs'!$N$6:$N$205,"Expired") -> 0 | G7: =COUNTIFS('Timing Runs'!$B$6:$B$205,$A7,'Timing Runs'!$N$6:$N$205,"Blocked") -> 0 | H7: =IF(C7=0,"",D7/C7) | I7: {=IF(SUMPRODUCT(('Timing Runs'!$B$6:$B$205=$A7)*ISNUMBER('Timing Runs'!$L$6:$L$205)*(('Timing Runs'!$N$6:$N$205="Delivered")+('Timing Runs'!$N$6:$N$205="Received; receipt pending"))*('Timing Runs'!$O$6:$O$205=""))=0,"",MIN(IF(('Timing Runs'!$B$6:$B$205=$A7)*ISNUMBER('Timing Runs'!$L$6:$L$205)*(('Timing Runs'!$N$6:$N$205="Delivered")+('Timing Runs'!$N$6:$N$205="Received; receipt pending"))*('Timing Runs'!$O$6:$O$205=""),'Timing Runs'!$L$6:$L$205)))} | J7: {=IF(SUMPRODUCT(('Timing Runs'!$B$6:$B$205=$A7)*ISNUMBER('Timing Runs'!$L$6:$L$205)*(('Timing Runs'!$N$6:$N$205="Delivered")+('Timing Runs'!$N$6:$N$205="Received; receipt pending"))*('Timing Runs'!$O$6:$O$205=""))=0,"",MEDIAN(IF(('Timing Runs'!$B$6:$B$205=$A7)*ISNUMBER('Timing Runs'!$L$6:$L$205)*(('Timing Runs'!$N$6:$N$205="Delivered")+('Timing Runs'!$N$6:$N$205="Received; receipt pending"))*('Timing Runs'!$O$6:$O$205=""),'Timing Runs'!$L$6:$L$205)))} | K7: {=IF(SUMPRODUCT(('Timing Runs'!$B$6:$B$205=$A7)*ISNUMBER('Timing Runs'!$L$6:$L$205)*(('Timing Runs'!$N$6:$N$205="Delivered")+('Timing Runs'!$N$6:$N$205="Received; receipt pending"))*('Timing Runs'!$O$6:$O$205=""))=0,"",MAX(IF(('Timing Runs'!$B$6:$B$205=$A7)*ISNUMBER('Timing Runs'!$L$6:$L$205)*(('Timing Runs'!$N$6:$N$205="Delivered")+('Timing Runs'!$N$6:$N$205="Received; receipt pending"))*('Timing Runs'!$O$6:$O$205=""),'Timing Runs'!$L$6:$L$205)))} | L7: {=IF(SUMPRODUCT(('Timing Runs'!$B$6:$B$205=$A7)*ISNUMBER('Timing Runs'!$M$6:$M$205)*('Timing Runs'!$N$6:$N$205="Delivered")*('Timing Runs'!$O$6:$O$205=""))=0,"",MIN(IF(('Timing Runs'!$B$6:$B$205=$A7)*ISNUMBER('Timing Runs'!$M$6:$M$205)*('Timing Runs'!$N$6:$N$205="Delivered")*('Timing Runs'!$O$6:$O$205=""),'Timing Runs'!$M$6:$M$205)))} | M7: {=IF(SUMPRODUCT(('Timing Runs'!$B$6:$B$205=$A7)*ISNUMBER('Timing Runs'!$M$6:$M$205)*('Timing Runs'!$N$6:$N$205="Delivered")*('Timing Runs'!$O$6:$O$205=""))=0,"",MEDIAN(IF(('Timing Runs'!$B$6:$B$205=$A7)*ISNUMBER('Timing Runs'!$M$6:$M$205)*('Timing Runs'!$N$6:$N$205="Delivered")*('Timing Runs'!$O$6:$O$205=""),'Timing Runs'!$M$6:$M$205)))} | N7: {=IF(SUMPRODUCT(('Timing Runs'!$B$6:$B$205=$A7)*ISNUMBER('Timing Runs'!$M$6:$M$205)*('Timing Runs'!$N$6:$N$205="Delivered")*('Timing Runs'!$O$6:$O$205=""))=0,"",MAX(IF(('Timing Runs'!$B$6:$B$205=$A7)*ISNUMBER('Timing Runs'!$M$6:$M$205)*('Timing Runs'!$N$6:$N$205="Delivered")*('Timing Runs'!$O$6:$O$205=""),'Timing Runs'!$M$6:$M$205)))}
A8: T03 | B8: Direct messaging with Internet unavailable | C8: =COUNTIFS('Timing Runs'!$B$6:$B$205,$A8,'Timing Runs'!$N$6:$N$205,"Delivered")+COUNTIFS('Timing Runs'!$B$6:$B$205,$A8,'Timing Runs'!$N$6:$N$205,"Received; receipt pending")+COUNTIFS('Timing Runs'!$B$6:$B$205,$A8,'Timing Runs'!$N$6:$N$205,"Failed")+COUNTIFS('Timing Runs'!$B$6:$B$205,$A8,'Timing Runs'!$N$6:$N$205,"Expired") -> 0 | D8: =COUNTIFS('Timing Runs'!$B$6:$B$205,$A8,'Timing Runs'!$N$6:$N$205,"Delivered")+COUNTIFS('Timing Runs'!$B$6:$B$205,$A8,'Timing Runs'!$N$6:$N$205,"Received; receipt pending") -> 0 | E8: =COUNTIFS('Timing Runs'!$B$6:$B$205,$A8,'Timing Runs'!$N$6:$N$205,"Failed") -> 0 | F8: =COUNTIFS('Timing Runs'!$B$6:$B$205,$A8,'Timing Runs'!$N$6:$N$205,"Expired") -> 0 | G8: =COUNTIFS('Timing Runs'!$B$6:$B$205,$A8,'Timing Runs'!$N$6:$N$205,"Blocked") -> 0 | H8: =IF(C8=0,"",D8/C8) | I8: {=IF(SUMPRODUCT(('Timing Runs'!$B$6:$B$205=$A8)*ISNUMBER('Timing Runs'!$L$6:$L$205)*(('Timing Runs'!$N$6:$N$205="Delivered")+('Timing Runs'!$N$6:$N$205="Received; receipt pending"))*('Timing Runs'!$O$6:$O$205=""))=0,"",MIN(IF(('Timing Runs'!$B$6:$B$205=$A8)*ISNUMBER('Timing Runs'!$L$6:$L$205)*(('Timing Runs'!$N$6:$N$205="Delivered")+('Timing Runs'!$N$6:$N$205="Received; receipt pending"))*('Timing Runs'!$O$6:$O$205=""),'Timing Runs'!$L$6:$L$205)))} | J8: {=IF(SUMPRODUCT(('Timing Runs'!$B$6:$B$205=$A8)*ISNUMBER('Timing Runs'!$L$6:$L$205)*(('Timing Runs'!$N$6:$N$205="Delivered")+('Timing Runs'!$N$6:$N$205="Received; receipt pending"))*('Timing Runs'!$O$6:$O$205=""))=0,"",MEDIAN(IF(('Timing Runs'!$B$6:$B$205=$A8)*ISNUMBER('Timing Runs'!$L$6:$L$205)*(('Timing Runs'!$N$6:$N$205="Delivered")+('Timing Runs'!$N$6:$N$205="Received; receipt pending"))*('Timing Runs'!$O$6:$O$205=""),'Timing Runs'!$L$6:$L$205)))} | K8: {=IF(SUMPRODUCT(('Timing Runs'!$B$6:$B$205=$A8)*ISNUMBER('Timing Runs'!$L$6:$L$205)*(('Timing Runs'!$N$6:$N$205="Delivered")+('Timing Runs'!$N$6:$N$205="Received; receipt pending"))*('Timing Runs'!$O$6:$O$205=""))=0,"",MAX(IF(('Timing Runs'!$B$6:$B$205=$A8)*ISNUMBER('Timing Runs'!$L$6:$L$205)*(('Timing Runs'!$N$6:$N$205="Delivered")+('Timing Runs'!$N$6:$N$205="Received; receipt pending"))*('Timing Runs'!$O$6:$O$205=""),'Timing Runs'!$L$6:$L$205)))} | L8: {=IF(SUMPRODUCT(('Timing Runs'!$B$6:$B$205=$A8)*ISNUMBER('Timing Runs'!$M$6:$M$205)*('Timing Runs'!$N$6:$N$205="Delivered")*('Timing Runs'!$O$6:$O$205=""))=0,"",MIN(IF(('Timing Runs'!$B$6:$B$205=$A8)*ISNUMBER('Timing Runs'!$M$6:$M$205)*('Timing Runs'!$N$6:$N$205="Delivered")*('Timing Runs'!$O$6:$O$205=""),'Timing Runs'!$M$6:$M$205)))} | M8: {=IF(SUMPRODUCT(('Timing Runs'!$B$6:$B$205=$A8)*ISNUMBER('Timing Runs'!$M$6:$M$205)*('Timing Runs'!$N$6:$N$205="Delivered")*('Timing Runs'!$O$6:$O$205=""))=0,"",MEDIAN(IF(('Timing Runs'!$B$6:$B$205=$A8)*ISNUMBER('Timing Runs'!$M$6:$M$205)*('Timing Runs'!$N$6:$N$205="Delivered")*('Timing Runs'!$O$6:$O$205=""),'Timing Runs'!$M$6:$M$205)))} | N8: {=IF(SUMPRODUCT(('Timing Runs'!$B$6:$B$205=$A8)*ISNUMBER('Timing Runs'!$M$6:$M$205)*('Timing Runs'!$N$6:$N$205="Delivered")*('Timing Runs'!$O$6:$O$205=""))=0,"",MAX(IF(('Timing Runs'!$B$6:$B$205=$A8)*ISNUMBER('Timing Runs'!$M$6:$M$205)*('Timing Runs'!$N$6:$N$205="Delivered")*('Timing Runs'!$O$6:$O$205=""),'Timing Runs'!$M$6:$M$205)))}
A9: T04 | B9: A to B to C with no direct A/C path | C9: =COUNTIFS('Timing Runs'!$B$6:$B$205,$A9,'Timing Runs'!$N$6:$N$205,"Delivered")+COUNTIFS('Timing Runs'!$B$6:$B$205,$A9,'Timing Runs'!$N$6:$N$205,"Received; receipt pending")+COUNTIFS('Timing Runs'!$B$6:$B$205,$A9,'Timing Runs'!$N$6:$N$205,"Failed")+COUNTIFS('Timing Runs'!$B$6:$B$205,$A9,'Timing Runs'!$N$6:$N$205,"Expired") -> 0 | D9: =COUNTIFS('Timing Runs'!$B$6:$B$205,$A9,'Timing Runs'!$N$6:$N$205,"Delivered")+COUNTIFS('Timing Runs'!$B$6:$B$205,$A9,'Timing Runs'!$N$6:$N$205,"Received; receipt pending") -> 0 | E9: =COUNTIFS('Timing Runs'!$B$6:$B$205,$A9,'Timing Runs'!$N$6:$N$205,"Failed") -> 0 | F9: =COUNTIFS('Timing Runs'!$B$6:$B$205,$A9,'Timing Runs'!$N$6:$N$205,"Expired") -> 0 | G9: =COUNTIFS('Timing Runs'!$B$6:$B$205,$A9,'Timing Runs'!$N$6:$N$205,"Blocked") -> 0 | H9: =IF(C9=0,"",D9/C9) | I9: {=IF(SUMPRODUCT(('Timing Runs'!$B$6:$B$205=$A9)*ISNUMBER('Timing Runs'!$L$6:$L$205)*(('Timing Runs'!$N$6:$N$205="Delivered")+('Timing Runs'!$N$6:$N$205="Received; receipt pending"))*('Timing Runs'!$O$6:$O$205=""))=0,"",MIN(IF(('Timing Runs'!$B$6:$B$205=$A9)*ISNUMBER('Timing Runs'!$L$6:$L$205)*(('Timing Runs'!$N$6:$N$205="Delivered")+('Timing Runs'!$N$6:$N$205="Received; receipt pending"))*('Timing Runs'!$O$6:$O$205=""),'Timing Runs'!$L$6:$L$205)))} | J9: {=IF(SUMPRODUCT(('Timing Runs'!$B$6:$B$205=$A9)*ISNUMBER('Timing Runs'!$L$6:$L$205)*(('Timing Runs'!$N$6:$N$205="Delivered")+('Timing Runs'!$N$6:$N$205="Received; receipt pending"))*('Timing Runs'!$O$6:$O$205=""))=0,"",MEDIAN(IF(('Timing Runs'!$B$6:$B$205=$A9)*ISNUMBER('Timing Runs'!$L$6:$L$205)*(('Timing Runs'!$N$6:$N$205="Delivered")+('Timing Runs'!$N$6:$N$205="Received; receipt pending"))*('Timing Runs'!$O$6:$O$205=""),'Timing Runs'!$L$6:$L$205)))} | K9: {=IF(SUMPRODUCT(('Timing Runs'!$B$6:$B$205=$A9)*ISNUMBER('Timing Runs'!$L$6:$L$205)*(('Timing Runs'!$N$6:$N$205="Delivered")+('Timing Runs'!$N$6:$N$205="Received; receipt pending"))*('Timing Runs'!$O$6:$O$205=""))=0,"",MAX(IF(('Timing Runs'!$B$6:$B$205=$A9)*ISNUMBER('Timing Runs'!$L$6:$L$205)*(('Timing Runs'!$N$6:$N$205="Delivered")+('Timing Runs'!$N$6:$N$205="Received; receipt pending"))*('Timing Runs'!$O$6:$O$205=""),'Timing Runs'!$L$6:$L$205)))} | L9: {=IF(SUMPRODUCT(('Timing Runs'!$B$6:$B$205=$A9)*ISNUMBER('Timing Runs'!$M$6:$M$205)*('Timing Runs'!$N$6:$N$205="Delivered")*('Timing Runs'!$O$6:$O$205=""))=0,"",MIN(IF(('Timing Runs'!$B$6:$B$205=$A9)*ISNUMBER('Timing Runs'!$M$6:$M$205)*('Timing Runs'!$N$6:$N$205="Delivered")*('Timing Runs'!$O$6:$O$205=""),'Timing Runs'!$M$6:$M$205)))} | M9: {=IF(SUMPRODUCT(('Timing Runs'!$B$6:$B$205=$A9)*ISNUMBER('Timing Runs'!$M$6:$M$205)*('Timing Runs'!$N$6:$N$205="Delivered")*('Timing Runs'!$O$6:$O$205=""))=0,"",MEDIAN(IF(('Timing Runs'!$B$6:$B$205=$A9)*ISNUMBER('Timing Runs'!$M$6:$M$205)*('Timing Runs'!$N$6:$N$205="Delivered")*('Timing Runs'!$O$6:$O$205=""),'Timing Runs'!$M$6:$M$205)))} | N9: {=IF(SUMPRODUCT(('Timing Runs'!$B$6:$B$205=$A9)*ISNUMBER('Timing Runs'!$M$6:$M$205)*('Timing Runs'!$N$6:$N$205="Delivered")*('Timing Runs'!$O$6:$O$205=""))=0,"",MAX(IF(('Timing Runs'!$B$6:$B$205=$A9)*ISNUMBER('Timing Runs'!$M$6:$M$205)*('Timing Runs'!$N$6:$N$205="Delivered")*('Timing Runs'!$O$6:$O$205=""),'Timing Runs'!$M$6:$M$205)))}
A10: T05 | B10: Relay custody must not mean Delivered | C10: =COUNTIFS('Timing Runs'!$B$6:$B$205,$A10,'Timing Runs'!$N$6:$N$205,"Delivered")+COUNTIFS('Timing Runs'!$B$6:$B$205,$A10,'Timing Runs'!$N$6:$N$205,"Received; receipt pending")+COUNTIFS('Timing Runs'!$B$6:$B$205,$A10,'Timing Runs'!$N$6:$N$205,"Failed")+COUNTIFS('Timing Runs'!$B$6:$B$205,$A10,'Timing Runs'!$N$6:$N$205,"Expired") -> 0 | D10: =COUNTIFS('Timing Runs'!$B$6:$B$205,$A10,'Timing Runs'!$N$6:$N$205,"Delivered")+COUNTIFS('Timing Runs'!$B$6:$B$205,$A10,'Timing Runs'!$N$6:$N$205,"Received; receipt pending") -> 0 | E10: =COUNTIFS('Timing Runs'!$B$6:$B$205,$A10,'Timing Runs'!$N$6:$N$205,"Failed") -> 0 | F10: =COUNTIFS('Timing Runs'!$B$6:$B$205,$A10,'Timing Runs'!$N$6:$N$205,"Expired") -> 0 | G10: =COUNTIFS('Timing Runs'!$B$6:$B$205,$A10,'Timing Runs'!$N$6:$N$205,"Blocked") -> 0 | H10: =IF(C10=0,"",D10/C10) | I10: {=IF(SUMPRODUCT(('Timing Runs'!$B$6:$B$205=$A10)*ISNUMBER('Timing Runs'!$L$6:$L$205)*(('Timing Runs'!$N$6:$N$205="Delivered")+('Timing Runs'!$N$6:$N$205="Received; receipt pending"))*('Timing Runs'!$O$6:$O$205=""))=0,"",MIN(IF(('Timing Runs'!$B$6:$B$205=$A10)*ISNUMBER('Timing Runs'!$L$6:$L$205)*(('Timing Runs'!$N$6:$N$205="Delivered")+('Timing Runs'!$N$6:$N$205="Received; receipt pending"))*('Timing Runs'!$O$6:$O$205=""),'Timing Runs'!$L$6:$L$205)))} | J10: {=IF(SUMPRODUCT(('Timing Runs'!$B$6:$B$205=$A10)*ISNUMBER('Timing Runs'!$L$6:$L$205)*(('Timing Runs'!$N$6:$N$205="Delivered")+('Timing Runs'!$N$6:$N$205="Received; receipt pending"))*('Timing Runs'!$O$6:$O$205=""))=0,"",MEDIAN(IF(('Timing Runs'!$B$6:$B$205=$A10)*ISNUMBER('Timing Runs'!$L$6:$L$205)*(('Timing Runs'!$N$6:$N$205="Delivered")+('Timing Runs'!$N$6:$N$205="Received; receipt pending"))*('Timing Runs'!$O$6:$O$205=""),'Timing Runs'!$L$6:$L$205)))} | K10: {=IF(SUMPRODUCT(('Timing Runs'!$B$6:$B$205=$A10)*ISNUMBER('Timing Runs'!$L$6:$L$205)*(('Timing Runs'!$N$6:$N$205="Delivered")+('Timing Runs'!$N$6:$N$205="Received; receipt pending"))*('Timing Runs'!$O$6:$O$205=""))=0,"",MAX(IF(('Timing Runs'!$B$6:$B$205=$A10)*ISNUMBER('Timing Runs'!$L$6:$L$205)*(('Timing Runs'!$N$6:$N$205="Delivered")+('Timing Runs'!$N$6:$N$205="Received; receipt pending"))*('Timing Runs'!$O$6:$O$205=""),'Timing Runs'!$L$6:$L$205)))} | L10: {=IF(SUMPRODUCT(('Timing Runs'!$B$6:$B$205=$A10)*ISNUMBER('Timing Runs'!$M$6:$M$205)*('Timing Runs'!$N$6:$N$205="Delivered")*('Timing Runs'!$O$6:$O$205=""))=0,"",MIN(IF(('Timing Runs'!$B$6:$B$205=$A10)*ISNUMBER('Timing Runs'!$M$6:$M$205)*('Timing Runs'!$N$6:$N$205="Delivered")*('Timing Runs'!$O$6:$O$205=""),'Timing Runs'!$M$6:$M$205)))} | M10: {=IF(SUMPRODUCT(('Timing Runs'!$B$6:$B$205=$A10)*ISNUMBER('Timing Runs'!$M$6:$M$205)*('Timing Runs'!$N$6:$N$205="Delivered")*('Timing Runs'!$O$6:$O$205=""))=0,"",MEDIAN(IF(('Timing Runs'!$B$6:$B$205=$A10)*ISNUMBER('Timing Runs'!$M$6:$M$205)*('Timing Runs'!$N$6:$N$205="Delivered")*('Timing Runs'!$O$6:$O$205=""),'Timing Runs'!$M$6:$M$205)))} | N10: {=IF(SUMPRODUCT(('Timing Runs'!$B$6:$B$205=$A10)*ISNUMBER('Timing Runs'!$M$6:$M$205)*('Timing Runs'!$N$6:$N$205="Delivered")*('Timing Runs'!$O$6:$O$205=""))=0,"",MAX(IF(('Timing Runs'!$B$6:$B$205=$A10)*ISNUMBER('Timing Runs'!$M$6:$M$205)*('Timing Runs'!$N$6:$N$205="Delivered")*('Timing Runs'!$O$6:$O$205=""),'Timing Runs'!$M$6:$M$205)))}
A11: T06 | B11: Courier delivery during a later encounter | C11: =COUNTIFS('Timing Runs'!$B$6:$B$205,$A11,'Timing Runs'!$N$6:$N$205,"Delivered")+COUNTIFS('Timing Runs'!$B$6:$B$205,$A11,'Timing Runs'!$N$6:$N$205,"Received; receipt pending")+COUNTIFS('Timing Runs'!$B$6:$B$205,$A11,'Timing Runs'!$N$6:$N$205,"Failed")+COUNTIFS('Timing Runs'!$B$6:$B$205,$A11,'Timing Runs'!$N$6:$N$205,"Expired") -> 0 | D11: =COUNTIFS('Timing Runs'!$B$6:$B$205,$A11,'Timing Runs'!$N$6:$N$205,"Delivered")+COUNTIFS('Timing Runs'!$B$6:$B$205,$A11,'Timing Runs'!$N$6:$N$205,"Received; receipt pending") -> 0 | E11: =COUNTIFS('Timing Runs'!$B$6:$B$205,$A11,'Timing Runs'!$N$6:$N$205,"Failed") -> 0 | F11: =COUNTIFS('Timing Runs'!$B$6:$B$205,$A11,'Timing Runs'!$N$6:$N$205,"Expired") -> 0 | G11: =COUNTIFS('Timing Runs'!$B$6:$B$205,$A11,'Timing Runs'!$N$6:$N$205,"Blocked") -> 0 | H11: =IF(C11=0,"",D11/C11) | I11: {=IF(SUMPRODUCT(('Timing Runs'!$B$6:$B$205=$A11)*ISNUMBER('Timing Runs'!$L$6:$L$205)*(('Timing Runs'!$N$6:$N$205="Delivered")+('Timing Runs'!$N$6:$N$205="Received; receipt pending"))*('Timing Runs'!$O$6:$O$205=""))=0,"",MIN(IF(('Timing Runs'!$B$6:$B$205=$A11)*ISNUMBER('Timing Runs'!$L$6:$L$205)*(('Timing Runs'!$N$6:$N$205="Delivered")+('Timing Runs'!$N$6:$N$205="Received; receipt pending"))*('Timing Runs'!$O$6:$O$205=""),'Timing Runs'!$L$6:$L$205)))} | J11: {=IF(SUMPRODUCT(('Timing Runs'!$B$6:$B$205=$A11)*ISNUMBER('Timing Runs'!$L$6:$L$205)*(('Timing Runs'!$N$6:$N$205="Delivered")+('Timing Runs'!$N$6:$N$205="Received; receipt pending"))*('Timing Runs'!$O$6:$O$205=""))=0,"",MEDIAN(IF(('Timing Runs'!$B$6:$B$205=$A11)*ISNUMBER('Timing Runs'!$L$6:$L$205)*(('Timing Runs'!$N$6:$N$205="Delivered")+('Timing Runs'!$N$6:$N$205="Received; receipt pending"))*('Timing Runs'!$O$6:$O$205=""),'Timing Runs'!$L$6:$L$205)))} | K11: {=IF(SUMPRODUCT(('Timing Runs'!$B$6:$B$205=$A11)*ISNUMBER('Timing Runs'!$L$6:$L$205)*(('Timing Runs'!$N$6:$N$205="Delivered")+('Timing Runs'!$N$6:$N$205="Received; receipt pending"))*('Timing Runs'!$O$6:$O$205=""))=0,"",MAX(IF(('Timing Runs'!$B$6:$B$205=$A11)*ISNUMBER('Timing Runs'!$L$6:$L$205)*(('Timing Runs'!$N$6:$N$205="Delivered")+('Timing Runs'!$N$6:$N$205="Received; receipt pending"))*('Timing Runs'!$O$6:$O$205=""),'Timing Runs'!$L$6:$L$205)))} | L11: {=IF(SUMPRODUCT(('Timing Runs'!$B$6:$B$205=$A11)*ISNUMBER('Timing Runs'!$M$6:$M$205)*('Timing Runs'!$N$6:$N$205="Delivered")*('Timing Runs'!$O$6:$O$205=""))=0,"",MIN(IF(('Timing Runs'!$B$6:$B$205=$A11)*ISNUMBER('Timing Runs'!$M$6:$M$205)*('Timing Runs'!$N$6:$N$205="Delivered")*('Timing Runs'!$O$6:$O$205=""),'Timing Runs'!$M$6:$M$205)))} | M11: {=IF(SUMPRODUCT(('Timing Runs'!$B$6:$B$205=$A11)*ISNUMBER('Timing Runs'!$M$6:$M$205)*('Timing Runs'!$N$6:$N$205="Delivered")*('Timing Runs'!$O$6:$O$205=""))=0,"",MEDIAN(IF(('Timing Runs'!$B$6:$B$205=$A11)*ISNUMBER('Timing Runs'!$M$6:$M$205)*('Timing Runs'!$N$6:$N$205="Delivered")*('Timing Runs'!$O$6:$O$205=""),'Timing Runs'!$M$6:$M$205)))} | N11: {=IF(SUMPRODUCT(('Timing Runs'!$B$6:$B$205=$A11)*ISNUMBER('Timing Runs'!$M$6:$M$205)*('Timing Runs'!$N$6:$N$205="Delivered")*('Timing Runs'!$O$6:$O$205=""))=0,"",MAX(IF(('Timing Runs'!$B$6:$B$205=$A11)*ISNUMBER('Timing Runs'!$M$6:$M$205)*('Timing Runs'!$N$6:$N$205="Delivered")*('Timing Runs'!$O$6:$O$205=""),'Timing Runs'!$M$6:$M$205)))}
A12: T07 | B12: Receipt returns after sender absence | C12: =COUNTIFS('Timing Runs'!$B$6:$B$205,$A12,'Timing Runs'!$N$6:$N$205,"Delivered")+COUNTIFS('Timing Runs'!$B$6:$B$205,$A12,'Timing Runs'!$N$6:$N$205,"Received; receipt pending")+COUNTIFS('Timing Runs'!$B$6:$B$205,$A12,'Timing Runs'!$N$6:$N$205,"Failed")+COUNTIFS('Timing Runs'!$B$6:$B$205,$A12,'Timing Runs'!$N$6:$N$205,"Expired") -> 0 | D12: =COUNTIFS('Timing Runs'!$B$6:$B$205,$A12,'Timing Runs'!$N$6:$N$205,"Delivered")+COUNTIFS('Timing Runs'!$B$6:$B$205,$A12,'Timing Runs'!$N$6:$N$205,"Received; receipt pending") -> 0 | E12: =COUNTIFS('Timing Runs'!$B$6:$B$205,$A12,'Timing Runs'!$N$6:$N$205,"Failed") -> 0 | F12: =COUNTIFS('Timing Runs'!$B$6:$B$205,$A12,'Timing Runs'!$N$6:$N$205,"Expired") -> 0 | G12: =COUNTIFS('Timing Runs'!$B$6:$B$205,$A12,'Timing Runs'!$N$6:$N$205,"Blocked") -> 0 | H12: =IF(C12=0,"",D12/C12) | I12: {=IF(SUMPRODUCT(('Timing Runs'!$B$6:$B$205=$A12)*ISNUMBER('Timing Runs'!$L$6:$L$205)*(('Timing Runs'!$N$6:$N$205="Delivered")+('Timing Runs'!$N$6:$N$205="Received; receipt pending"))*('Timing Runs'!$O$6:$O$205=""))=0,"",MIN(IF(('Timing Runs'!$B$6:$B$205=$A12)*ISNUMBER('Timing Runs'!$L$6:$L$205)*(('Timing Runs'!$N$6:$N$205="Delivered")+('Timing Runs'!$N$6:$N$205="Received; receipt pending"))*('Timing Runs'!$O$6:$O$205=""),'Timing Runs'!$L$6:$L$205)))} | J12: {=IF(SUMPRODUCT(('Timing Runs'!$B$6:$B$205=$A12)*ISNUMBER('Timing Runs'!$L$6:$L$205)*(('Timing Runs'!$N$6:$N$205="Delivered")+('Timing Runs'!$N$6:$N$205="Received; receipt pending"))*('Timing Runs'!$O$6:$O$205=""))=0,"",MEDIAN(IF(('Timing Runs'!$B$6:$B$205=$A12)*ISNUMBER('Timing Runs'!$L$6:$L$205)*(('Timing Runs'!$N$6:$N$205="Delivered")+('Timing Runs'!$N$6:$N$205="Received; receipt pending"))*('Timing Runs'!$O$6:$O$205=""),'Timing Runs'!$L$6:$L$205)))} | K12: {=IF(SUMPRODUCT(('Timing Runs'!$B$6:$B$205=$A12)*ISNUMBER('Timing Runs'!$L$6:$L$205)*(('Timing Runs'!$N$6:$N$205="Delivered")+('Timing Runs'!$N$6:$N$205="Received; receipt pending"))*('Timing Runs'!$O$6:$O$205=""))=0,"",MAX(IF(('Timing Runs'!$B$6:$B$205=$A12)*ISNUMBER('Timing Runs'!$L$6:$L$205)*(('Timing Runs'!$N$6:$N$205="Delivered")+('Timing Runs'!$N$6:$N$205="Received; receipt pending"))*('Timing Runs'!$O$6:$O$205=""),'Timing Runs'!$L$6:$L$205)))} | L12: {=IF(SUMPRODUCT(('Timing Runs'!$B$6:$B$205=$A12)*ISNUMBER('Timing Runs'!$M$6:$M$205)*('Timing Runs'!$N$6:$N$205="Delivered")*('Timing Runs'!$O$6:$O$205=""))=0,"",MIN(IF(('Timing Runs'!$B$6:$B$205=$A12)*ISNUMBER('Timing Runs'!$M$6:$M$205)*('Timing Runs'!$N$6:$N$205="Delivered")*('Timing Runs'!$O$6:$O$205=""),'Timing Runs'!$M$6:$M$205)))} | M12: {=IF(SUMPRODUCT(('Timing Runs'!$B$6:$B$205=$A12)*ISNUMBER('Timing Runs'!$M$6:$M$205)*('Timing Runs'!$N$6:$N$205="Delivered")*('Timing Runs'!$O$6:$O$205=""))=0,"",MEDIAN(IF(('Timing Runs'!$B$6:$B$205=$A12)*ISNUMBER('Timing Runs'!$M$6:$M$205)*('Timing Runs'!$N$6:$N$205="Delivered")*('Timing Runs'!$O$6:$O$205=""),'Timing Runs'!$M$6:$M$205)))} | N12: {=IF(SUMPRODUCT(('Timing Runs'!$B$6:$B$205=$A12)*ISNUMBER('Timing Runs'!$M$6:$M$205)*('Timing Runs'!$N$6:$N$205="Delivered")*('Timing Runs'!$O$6:$O$205=""))=0,"",MAX(IF(('Timing Runs'!$B$6:$B$205=$A12)*ISNUMBER('Timing Runs'!$M$6:$M$205)*('Timing Runs'!$N$6:$N$205="Delivered")*('Timing Runs'!$O$6:$O$205=""),'Timing Runs'!$M$6:$M$205)))}
A13: T08 | B13: Restart relay after confirmed custody | C13: =COUNTIFS('Timing Runs'!$B$6:$B$205,$A13,'Timing Runs'!$N$6:$N$205,"Delivered")+COUNTIFS('Timing Runs'!$B$6:$B$205,$A13,'Timing Runs'!$N$6:$N$205,"Received; receipt pending")+COUNTIFS('Timing Runs'!$B$6:$B$205,$A13,'Timing Runs'!$N$6:$N$205,"Failed")+COUNTIFS('Timing Runs'!$B$6:$B$205,$A13,'Timing Runs'!$N$6:$N$205,"Expired") -> 0 | D13: =COUNTIFS('Timing Runs'!$B$6:$B$205,$A13,'Timing Runs'!$N$6:$N$205,"Delivered")+COUNTIFS('Timing Runs'!$B$6:$B$205,$A13,'Timing Runs'!$N$6:$N$205,"Received; receipt pending") -> 0 | E13: =COUNTIFS('Timing Runs'!$B$6:$B$205,$A13,'Timing Runs'!$N$6:$N$205,"Failed") -> 0 | F13: =COUNTIFS('Timing Runs'!$B$6:$B$205,$A13,'Timing Runs'!$N$6:$N$205,"Expired") -> 0 | G13: =COUNTIFS('Timing Runs'!$B$6:$B$205,$A13,'Timing Runs'!$N$6:$N$205,"Blocked") -> 0 | H13: =IF(C13=0,"",D13/C13) | I13: {=IF(SUMPRODUCT(('Timing Runs'!$B$6:$B$205=$A13)*ISNUMBER('Timing Runs'!$L$6:$L$205)*(('Timing Runs'!$N$6:$N$205="Delivered")+('Timing Runs'!$N$6:$N$205="Received; receipt pending"))*('Timing Runs'!$O$6:$O$205=""))=0,"",MIN(IF(('Timing Runs'!$B$6:$B$205=$A13)*ISNUMBER('Timing Runs'!$L$6:$L$205)*(('Timing Runs'!$N$6:$N$205="Delivered")+('Timing Runs'!$N$6:$N$205="Received; receipt pending"))*('Timing Runs'!$O$6:$O$205=""),'Timing Runs'!$L$6:$L$205)))} | J13: {=IF(SUMPRODUCT(('Timing Runs'!$B$6:$B$205=$A13)*ISNUMBER('Timing Runs'!$L$6:$L$205)*(('Timing Runs'!$N$6:$N$205="Delivered")+('Timing Runs'!$N$6:$N$205="Received; receipt pending"))*('Timing Runs'!$O$6:$O$205=""))=0,"",MEDIAN(IF(('Timing Runs'!$B$6:$B$205=$A13)*ISNUMBER('Timing Runs'!$L$6:$L$205)*(('Timing Runs'!$N$6:$N$205="Delivered")+('Timing Runs'!$N$6:$N$205="Received; receipt pending"))*('Timing Runs'!$O$6:$O$205=""),'Timing Runs'!$L$6:$L$205)))} | K13: {=IF(SUMPRODUCT(('Timing Runs'!$B$6:$B$205=$A13)*ISNUMBER('Timing Runs'!$L$6:$L$205)*(('Timing Runs'!$N$6:$N$205="Delivered")+('Timing Runs'!$N$6:$N$205="Received; receipt pending"))*('Timing Runs'!$O$6:$O$205=""))=0,"",MAX(IF(('Timing Runs'!$B$6:$B$205=$A13)*ISNUMBER('Timing Runs'!$L$6:$L$205)*(('Timing Runs'!$N$6:$N$205="Delivered")+('Timing Runs'!$N$6:$N$205="Received; receipt pending"))*('Timing Runs'!$O$6:$O$205=""),'Timing Runs'!$L$6:$L$205)))} | L13: {=IF(SUMPRODUCT(('Timing Runs'!$B$6:$B$205=$A13)*ISNUMBER('Timing Runs'!$M$6:$M$205)*('Timing Runs'!$N$6:$N$205="Delivered")*('Timing Runs'!$O$6:$O$205=""))=0,"",MIN(IF(('Timing Runs'!$B$6:$B$205=$A13)*ISNUMBER('Timing Runs'!$M$6:$M$205)*('Timing Runs'!$N$6:$N$205="Delivered")*('Timing Runs'!$O$6:$O$205=""),'Timing Runs'!$M$6:$M$205)))} | M13: {=IF(SUMPRODUCT(('Timing Runs'!$B$6:$B$205=$A13)*ISNUMBER('Timing Runs'!$M$6:$M$205)*('Timing Runs'!$N$6:$N$205="Delivered")*('Timing Runs'!$O$6:$O$205=""))=0,"",MEDIAN(IF(('Timing Runs'!$B$6:$B$205=$A13)*ISNUMBER('Timing Runs'!$M$6:$M$205)*('Timing Runs'!$N$6:$N$205="Delivered")*('Timing Runs'!$O$6:$O$205=""),'Timing Runs'!$M$6:$M$205)))} | N13: {=IF(SUMPRODUCT(('Timing Runs'!$B$6:$B$205=$A13)*ISNUMBER('Timing Runs'!$M$6:$M$205)*('Timing Runs'!$N$6:$N$205="Delivered")*('Timing Runs'!$O$6:$O$205=""))=0,"",MAX(IF(('Timing Runs'!$B$6:$B$205=$A13)*ISNUMBER('Timing Runs'!$M$6:$M$205)*('Timing Runs'!$N$6:$N$205="Delivered")*('Timing Runs'!$O$6:$O$205=""),'Timing Runs'!$M$6:$M$205)))}
A14: T09 | B14: Locked relay with existing connections | C14: =COUNTIFS('Timing Runs'!$B$6:$B$205,$A14,'Timing Runs'!$N$6:$N$205,"Delivered")+COUNTIFS('Timing Runs'!$B$6:$B$205,$A14,'Timing Runs'!$N$6:$N$205,"Received; receipt pending")+COUNTIFS('Timing Runs'!$B$6:$B$205,$A14,'Timing Runs'!$N$6:$N$205,"Failed")+COUNTIFS('Timing Runs'!$B$6:$B$205,$A14,'Timing Runs'!$N$6:$N$205,"Expired") -> 0 | D14: =COUNTIFS('Timing Runs'!$B$6:$B$205,$A14,'Timing Runs'!$N$6:$N$205,"Delivered")+COUNTIFS('Timing Runs'!$B$6:$B$205,$A14,'Timing Runs'!$N$6:$N$205,"Received; receipt pending") -> 0 | E14: =COUNTIFS('Timing Runs'!$B$6:$B$205,$A14,'Timing Runs'!$N$6:$N$205,"Failed") -> 0 | F14: =COUNTIFS('Timing Runs'!$B$6:$B$205,$A14,'Timing Runs'!$N$6:$N$205,"Expired") -> 0 | G14: =COUNTIFS('Timing Runs'!$B$6:$B$205,$A14,'Timing Runs'!$N$6:$N$205,"Blocked") -> 0 | H14: =IF(C14=0,"",D14/C14) | I14: {=IF(SUMPRODUCT(('Timing Runs'!$B$6:$B$205=$A14)*ISNUMBER('Timing Runs'!$L$6:$L$205)*(('Timing Runs'!$N$6:$N$205="Delivered")+('Timing Runs'!$N$6:$N$205="Received; receipt pending"))*('Timing Runs'!$O$6:$O$205=""))=0,"",MIN(IF(('Timing Runs'!$B$6:$B$205=$A14)*ISNUMBER('Timing Runs'!$L$6:$L$205)*(('Timing Runs'!$N$6:$N$205="Delivered")+('Timing Runs'!$N$6:$N$205="Received; receipt pending"))*('Timing Runs'!$O$6:$O$205=""),'Timing Runs'!$L$6:$L$205)))} | J14: {=IF(SUMPRODUCT(('Timing Runs'!$B$6:$B$205=$A14)*ISNUMBER('Timing Runs'!$L$6:$L$205)*(('Timing Runs'!$N$6:$N$205="Delivered")+('Timing Runs'!$N$6:$N$205="Received; receipt pending"))*('Timing Runs'!$O$6:$O$205=""))=0,"",MEDIAN(IF(('Timing Runs'!$B$6:$B$205=$A14)*ISNUMBER('Timing Runs'!$L$6:$L$205)*(('Timing Runs'!$N$6:$N$205="Delivered")+('Timing Runs'!$N$6:$N$205="Received; receipt pending"))*('Timing Runs'!$O$6:$O$205=""),'Timing Runs'!$L$6:$L$205)))} | K14: {=IF(SUMPRODUCT(('Timing Runs'!$B$6:$B$205=$A14)*ISNUMBER('Timing Runs'!$L$6:$L$205)*(('Timing Runs'!$N$6:$N$205="Delivered")+('Timing Runs'!$N$6:$N$205="Received; receipt pending"))*('Timing Runs'!$O$6:$O$205=""))=0,"",MAX(IF(('Timing Runs'!$B$6:$B$205=$A14)*ISNUMBER('Timing Runs'!$L$6:$L$205)*(('Timing Runs'!$N$6:$N$205="Delivered")+('Timing Runs'!$N$6:$N$205="Received; receipt pending"))*('Timing Runs'!$O$6:$O$205=""),'Timing Runs'!$L$6:$L$205)))} | L14: {=IF(SUMPRODUCT(('Timing Runs'!$B$6:$B$205=$A14)*ISNUMBER('Timing Runs'!$M$6:$M$205)*('Timing Runs'!$N$6:$N$205="Delivered")*('Timing Runs'!$O$6:$O$205=""))=0,"",MIN(IF(('Timing Runs'!$B$6:$B$205=$A14)*ISNUMBER('Timing Runs'!$M$6:$M$205)*('Timing Runs'!$N$6:$N$205="Delivered")*('Timing Runs'!$O$6:$O$205=""),'Timing Runs'!$M$6:$M$205)))} | M14: {=IF(SUMPRODUCT(('Timing Runs'!$B$6:$B$205=$A14)*ISNUMBER('Timing Runs'!$M$6:$M$205)*('Timing Runs'!$N$6:$N$205="Delivered")*('Timing Runs'!$O$6:$O$205=""))=0,"",MEDIAN(IF(('Timing Runs'!$B$6:$B$205=$A14)*ISNUMBER('Timing Runs'!$M$6:$M$205)*('Timing Runs'!$N$6:$N$205="Delivered")*('Timing Runs'!$O$6:$O$205=""),'Timing Runs'!$M$6:$M$205)))} | N14: {=IF(SUMPRODUCT(('Timing Runs'!$B$6:$B$205=$A14)*ISNUMBER('Timing Runs'!$M$6:$M$205)*('Timing Runs'!$N$6:$N$205="Delivered")*('Timing Runs'!$O$6:$O$205=""))=0,"",MAX(IF(('Timing Runs'!$B$6:$B$205=$A14)*ISNUMBER('Timing Runs'!$M$6:$M$205)*('Timing Runs'!$N$6:$N$205="Delivered")*('Timing Runs'!$O$6:$O$205=""),'Timing Runs'!$M$6:$M$205)))}
